[2023-12-03 14:29:44,143] {taskinstance.py:903} INFO - Dependencies all met for <TaskInstance: meeting.clean_answers 2023-12-03T14:29:39.393598+00:00 [queued]>
[2023-12-03 14:29:44,152] {taskinstance.py:903} INFO - Dependencies all met for <TaskInstance: meeting.clean_answers 2023-12-03T14:29:39.393598+00:00 [queued]>
[2023-12-03 14:29:44,153] {taskinstance.py:1095} INFO - 
--------------------------------------------------------------------------------
[2023-12-03 14:29:44,153] {taskinstance.py:1096} INFO - Starting attempt 1 of 1
[2023-12-03 14:29:44,153] {taskinstance.py:1097} INFO - 
--------------------------------------------------------------------------------
[2023-12-03 14:29:44,166] {taskinstance.py:1115} INFO - Executing <Task(PythonOperator): clean_answers> on 2023-12-03T14:29:39.393598+00:00
[2023-12-03 14:29:44,170] {standard_task_runner.py:52} INFO - Started process 1782 to run task
[2023-12-03 14:29:44,173] {standard_task_runner.py:76} INFO - Running: ['***', 'tasks', 'run', 'meeting', 'clean_answers', '2023-12-03T14:29:39.393598+00:00', '--job-id', '57', '--pool', 'default_pool', '--raw', '--subdir', 'DAGS_FOLDER/first_dag.py', '--cfg-path', '/tmp/tmpx6_alckq', '--error-file', '/tmp/tmp1savlp8m']
[2023-12-03 14:29:44,175] {standard_task_runner.py:77} INFO - Job 57: Subtask clean_answers
[2023-12-03 14:29:44,212] {logging_mixin.py:109} INFO - Running <TaskInstance: meeting.clean_answers 2023-12-03T14:29:39.393598+00:00 [running]> on host 9d53e6732d94
[2023-12-03 14:29:44,261] {taskinstance.py:1254} INFO - Exporting the following env vars:
AIRFLOW_CTX_DAG_OWNER=***
AIRFLOW_CTX_DAG_ID=meeting
AIRFLOW_CTX_TASK_ID=clean_answers
AIRFLOW_CTX_EXECUTION_DATE=2023-12-03T14:29:39.393598+00:00
AIRFLOW_CTX_DAG_RUN_ID=manual__2023-12-03T14:29:39.393598+00:00
[2023-12-03 14:29:44,262] {taskinstance.py:1463} ERROR - Task failed with exception
Traceback (most recent call last):
  File "/home/airflow/.local/lib/python3.6/site-packages/airflow/models/taskinstance.py", line 1165, in _run_raw_task
    self._prepare_and_execute_task_with_callbacks(context, task)
  File "/home/airflow/.local/lib/python3.6/site-packages/airflow/models/taskinstance.py", line 1283, in _prepare_and_execute_task_with_callbacks
    result = self._execute_task(context, task_copy)
  File "/home/airflow/.local/lib/python3.6/site-packages/airflow/models/taskinstance.py", line 1313, in _execute_task
    result = task_copy.execute(context=context)
  File "/home/airflow/.local/lib/python3.6/site-packages/airflow/operators/python.py", line 150, in execute
    return_value = self.execute_callable()
  File "/home/airflow/.local/lib/python3.6/site-packages/airflow/operators/python.py", line 161, in execute_callable
    return self.python_callable(*self.op_args, **self.op_kwargs)
TypeError: clean_answer() missing 1 required positional argument: 'output_ans'
[2023-12-03 14:29:44,264] {taskinstance.py:1513} INFO - Marking task as FAILED. dag_id=meeting, task_id=clean_answers, execution_date=20231203T142939, start_date=20231203T142944, end_date=20231203T142944
[2023-12-03 14:29:44,304] {local_task_job.py:151} INFO - Task exited with return code 1
[2023-12-03 14:29:44,323] {local_task_job.py:261} INFO - 0 downstream tasks scheduled from follow-on schedule check
