[2023-12-02 11:15:25,313] {taskinstance.py:903} INFO - Dependencies all met for <TaskInstance: i_can_do_it_and_i_will_do.get_data 2023-12-02T11:15:24.271067+00:00 [queued]>
[2023-12-02 11:15:25,329] {taskinstance.py:903} INFO - Dependencies all met for <TaskInstance: i_can_do_it_and_i_will_do.get_data 2023-12-02T11:15:24.271067+00:00 [queued]>
[2023-12-02 11:15:25,329] {taskinstance.py:1095} INFO - 
--------------------------------------------------------------------------------
[2023-12-02 11:15:25,330] {taskinstance.py:1096} INFO - Starting attempt 1 of 1
[2023-12-02 11:15:25,330] {taskinstance.py:1097} INFO - 
--------------------------------------------------------------------------------
[2023-12-02 11:15:25,339] {taskinstance.py:1115} INFO - Executing <Task(PythonOperator): get_data> on 2023-12-02T11:15:24.271067+00:00
[2023-12-02 11:15:25,344] {standard_task_runner.py:52} INFO - Started process 1037 to run task
[2023-12-02 11:15:25,347] {standard_task_runner.py:76} INFO - Running: ['***', 'tasks', 'run', 'i_can_do_it_and_i_will_do', 'get_data', '2023-12-02T11:15:24.271067+00:00', '--job-id', '16', '--pool', 'default_pool', '--raw', '--subdir', 'DAGS_FOLDER/first_dag.py', '--cfg-path', '/tmp/tmp8oim_hbx', '--error-file', '/tmp/tmp10fy7fx8']
[2023-12-02 11:15:25,350] {standard_task_runner.py:77} INFO - Job 16: Subtask get_data
[2023-12-02 11:15:25,392] {logging_mixin.py:109} INFO - Running <TaskInstance: i_can_do_it_and_i_will_do.get_data 2023-12-02T11:15:24.271067+00:00 [running]> on host d063d0a6f382
[2023-12-02 11:15:25,442] {taskinstance.py:1254} INFO - Exporting the following env vars:
AIRFLOW_CTX_DAG_OWNER=***
AIRFLOW_CTX_DAG_ID=i_can_do_it_and_i_will_do
AIRFLOW_CTX_TASK_ID=get_data
AIRFLOW_CTX_EXECUTION_DATE=2023-12-02T11:15:24.271067+00:00
AIRFLOW_CTX_DAG_RUN_ID=manual__2023-12-02T11:15:24.271067+00:00
[2023-12-02 11:15:26,892] {taskinstance.py:1463} ERROR - Task failed with exception
Traceback (most recent call last):
  File "/home/airflow/.local/lib/python3.6/site-packages/airflow/models/taskinstance.py", line 1165, in _run_raw_task
    self._prepare_and_execute_task_with_callbacks(context, task)
  File "/home/airflow/.local/lib/python3.6/site-packages/airflow/models/taskinstance.py", line 1283, in _prepare_and_execute_task_with_callbacks
    result = self._execute_task(context, task_copy)
  File "/home/airflow/.local/lib/python3.6/site-packages/airflow/models/taskinstance.py", line 1313, in _execute_task
    result = task_copy.execute(context=context)
  File "/home/airflow/.local/lib/python3.6/site-packages/airflow/operators/python.py", line 150, in execute
    return_value = self.execute_callable()
  File "/home/airflow/.local/lib/python3.6/site-packages/airflow/operators/python.py", line 161, in execute_callable
    return self.python_callable(*self.op_args, **self.op_kwargs)
  File "/opt/airflow/dags/first_dag.py", line 16, in get_data
    df.to_csv(output_meet, index = False)
  File "/home/airflow/.local/lib/python3.6/site-packages/pandas/core/generic.py", line 3170, in to_csv
    formatter.save()
  File "/home/airflow/.local/lib/python3.6/site-packages/pandas/io/formats/csvs.py", line 190, in save
    compression=dict(self.compression_args, method=self.compression),
  File "/home/airflow/.local/lib/python3.6/site-packages/pandas/io/common.py", line 493, in get_handle
    f = open(path_or_buf, mode, encoding=encoding, errors=errors, newline="")
FileNotFoundError: [Errno 2] No such file or directory: '/home/tnanun/airflow-meet/data/data.csv'
[2023-12-02 11:15:26,894] {taskinstance.py:1513} INFO - Marking task as FAILED. dag_id=i_can_do_it_and_i_will_do, task_id=get_data, execution_date=20231202T111524, start_date=20231202T111525, end_date=20231202T111526
[2023-12-02 11:15:26,925] {local_task_job.py:151} INFO - Task exited with return code 1
[2023-12-02 11:15:26,946] {local_task_job.py:261} INFO - 0 downstream tasks scheduled from follow-on schedule check
