[2023-12-03 10:00:07,422] {taskinstance.py:903} INFO - Dependencies all met for <TaskInstance: meeting.clean_answers 2023-12-03T10:00:00.448350+00:00 [queued]>
[2023-12-03 10:00:07,438] {taskinstance.py:903} INFO - Dependencies all met for <TaskInstance: meeting.clean_answers 2023-12-03T10:00:00.448350+00:00 [queued]>
[2023-12-03 10:00:07,438] {taskinstance.py:1095} INFO - 
--------------------------------------------------------------------------------
[2023-12-03 10:00:07,438] {taskinstance.py:1096} INFO - Starting attempt 1 of 1
[2023-12-03 10:00:07,438] {taskinstance.py:1097} INFO - 
--------------------------------------------------------------------------------
[2023-12-03 10:00:07,448] {taskinstance.py:1115} INFO - Executing <Task(PythonOperator): clean_answers> on 2023-12-03T10:00:00.448350+00:00
[2023-12-03 10:00:07,454] {standard_task_runner.py:52} INFO - Started process 1141 to run task
[2023-12-03 10:00:07,457] {standard_task_runner.py:76} INFO - Running: ['***', 'tasks', 'run', 'meeting', 'clean_answers', '2023-12-03T10:00:00.448350+00:00', '--job-id', '45', '--pool', 'default_pool', '--raw', '--subdir', 'DAGS_FOLDER/first_dag.py', '--cfg-path', '/tmp/tmplf3cbcgh', '--error-file', '/tmp/tmpauoqefzd']
[2023-12-03 10:00:07,459] {standard_task_runner.py:77} INFO - Job 45: Subtask clean_answers
[2023-12-03 10:00:07,494] {logging_mixin.py:109} INFO - Running <TaskInstance: meeting.clean_answers 2023-12-03T10:00:00.448350+00:00 [running]> on host 2dc0f840af49
[2023-12-03 10:00:07,537] {taskinstance.py:1254} INFO - Exporting the following env vars:
AIRFLOW_CTX_DAG_OWNER=***
AIRFLOW_CTX_DAG_ID=meeting
AIRFLOW_CTX_TASK_ID=clean_answers
AIRFLOW_CTX_EXECUTION_DATE=2023-12-03T10:00:00.448350+00:00
AIRFLOW_CTX_DAG_RUN_ID=manual__2023-12-03T10:00:00.448350+00:00
[2023-12-03 10:00:07,538] {taskinstance.py:1463} ERROR - Task failed with exception
Traceback (most recent call last):
  File "/home/airflow/.local/lib/python3.6/site-packages/airflow/models/taskinstance.py", line 1165, in _run_raw_task
    self._prepare_and_execute_task_with_callbacks(context, task)
  File "/home/airflow/.local/lib/python3.6/site-packages/airflow/models/taskinstance.py", line 1283, in _prepare_and_execute_task_with_callbacks
    result = self._execute_task(context, task_copy)
  File "/home/airflow/.local/lib/python3.6/site-packages/airflow/models/taskinstance.py", line 1313, in _execute_task
    result = task_copy.execute(context=context)
  File "/home/airflow/.local/lib/python3.6/site-packages/airflow/operators/python.py", line 150, in execute
    return_value = self.execute_callable()
  File "/home/airflow/.local/lib/python3.6/site-packages/airflow/operators/python.py", line 161, in execute_callable
    return self.python_callable(*self.op_args, **self.op_kwargs)
TypeError: clean_answer() missing 1 required positional argument: 'output_ans'
[2023-12-03 10:00:07,540] {taskinstance.py:1513} INFO - Marking task as FAILED. dag_id=meeting, task_id=clean_answers, execution_date=20231203T100000, start_date=20231203T100007, end_date=20231203T100007
[2023-12-03 10:00:07,589] {local_task_job.py:151} INFO - Task exited with return code 1
[2023-12-03 10:00:07,608] {local_task_job.py:261} INFO - 0 downstream tasks scheduled from follow-on schedule check
