[2024-03-10 16:19:15,111] {taskinstance.py:903} INFO - Dependencies all met for <TaskInstance: meeting_project492.merge_data 2024-03-10T16:19:08.089573+00:00 [queued]>
[2024-03-10 16:19:15,122] {taskinstance.py:903} INFO - Dependencies all met for <TaskInstance: meeting_project492.merge_data 2024-03-10T16:19:08.089573+00:00 [queued]>
[2024-03-10 16:19:15,122] {taskinstance.py:1095} INFO - 
--------------------------------------------------------------------------------
[2024-03-10 16:19:15,122] {taskinstance.py:1096} INFO - Starting attempt 1 of 1
[2024-03-10 16:19:15,122] {taskinstance.py:1097} INFO - 
--------------------------------------------------------------------------------
[2024-03-10 16:19:15,135] {taskinstance.py:1115} INFO - Executing <Task(PythonOperator): merge_data> on 2024-03-10T16:19:08.089573+00:00
[2024-03-10 16:19:15,140] {standard_task_runner.py:52} INFO - Started process 2051 to run task
[2024-03-10 16:19:15,143] {standard_task_runner.py:76} INFO - Running: ['***', 'tasks', 'run', 'meeting_project492', 'merge_data', '2024-03-10T16:19:08.089573+00:00', '--job-id', '417', '--pool', 'default_pool', '--raw', '--subdir', 'DAGS_FOLDER/first_dag.py', '--cfg-path', '/tmp/tmp48zidhal', '--error-file', '/tmp/tmp4lwggfrj']
[2024-03-10 16:19:15,145] {standard_task_runner.py:77} INFO - Job 417: Subtask merge_data
[2024-03-10 16:19:15,179] {logging_mixin.py:109} INFO - Running <TaskInstance: meeting_project492.merge_data 2024-03-10T16:19:08.089573+00:00 [running]> on host 6053b7d19b63
[2024-03-10 16:19:15,233] {taskinstance.py:1254} INFO - Exporting the following env vars:
AIRFLOW_CTX_DAG_OWNER=***
AIRFLOW_CTX_DAG_ID=meeting_project492
AIRFLOW_CTX_TASK_ID=merge_data
AIRFLOW_CTX_EXECUTION_DATE=2024-03-10T16:19:08.089573+00:00
AIRFLOW_CTX_DAG_RUN_ID=manual__2024-03-10T16:19:08.089573+00:00
[2024-03-10 16:19:15,270] {taskinstance.py:1463} ERROR - Task failed with exception
Traceback (most recent call last):
  File "/home/airflow/.local/lib/python3.6/site-packages/airflow/models/taskinstance.py", line 1165, in _run_raw_task
    self._prepare_and_execute_task_with_callbacks(context, task)
  File "/home/airflow/.local/lib/python3.6/site-packages/airflow/models/taskinstance.py", line 1283, in _prepare_and_execute_task_with_callbacks
    result = self._execute_task(context, task_copy)
  File "/home/airflow/.local/lib/python3.6/site-packages/airflow/models/taskinstance.py", line 1313, in _execute_task
    result = task_copy.execute(context=context)
  File "/home/airflow/.local/lib/python3.6/site-packages/airflow/operators/python.py", line 150, in execute
    return_value = self.execute_callable()
  File "/home/airflow/.local/lib/python3.6/site-packages/airflow/operators/python.py", line 161, in execute_callable
    return self.python_callable(*self.op_args, **self.op_kwargs)
  File "/opt/airflow/dags/first_dag.py", line 106, in merge_data
    df_meet_fol_ans_com_obj['no_ans'] = df_meet_fol_ans_com_obj['no_ans'].astype(int)
  File "/home/airflow/.local/lib/python3.6/site-packages/pandas/core/generic.py", line 5548, in astype
    new_data = self._mgr.astype(dtype=dtype, copy=copy, errors=errors,)
  File "/home/airflow/.local/lib/python3.6/site-packages/pandas/core/internals/managers.py", line 604, in astype
    return self.apply("astype", dtype=dtype, copy=copy, errors=errors)
  File "/home/airflow/.local/lib/python3.6/site-packages/pandas/core/internals/managers.py", line 409, in apply
    applied = getattr(b, f)(**kwargs)
  File "/home/airflow/.local/lib/python3.6/site-packages/pandas/core/internals/blocks.py", line 595, in astype
    values = astype_nansafe(vals1d, dtype, copy=True)
  File "/home/airflow/.local/lib/python3.6/site-packages/pandas/core/dtypes/cast.py", line 968, in astype_nansafe
    raise ValueError("Cannot convert non-finite values (NA or inf) to integer")
ValueError: Cannot convert non-finite values (NA or inf) to integer
[2024-03-10 16:19:15,274] {taskinstance.py:1513} INFO - Marking task as FAILED. dag_id=meeting_project492, task_id=merge_data, execution_date=20240310T161908, start_date=20240310T161915, end_date=20240310T161915
[2024-03-10 16:19:15,315] {local_task_job.py:151} INFO - Task exited with return code 1
[2024-03-10 16:19:15,335] {local_task_job.py:261} INFO - 0 downstream tasks scheduled from follow-on schedule check
