[2024-03-11 04:34:02,706] {taskinstance.py:903} INFO - Dependencies all met for <TaskInstance: meeting_project492.clean_answers 2024-03-11T04:33:59.355517+00:00 [queued]>
[2024-03-11 04:34:02,720] {taskinstance.py:903} INFO - Dependencies all met for <TaskInstance: meeting_project492.clean_answers 2024-03-11T04:33:59.355517+00:00 [queued]>
[2024-03-11 04:34:02,721] {taskinstance.py:1095} INFO - 
--------------------------------------------------------------------------------
[2024-03-11 04:34:02,721] {taskinstance.py:1096} INFO - Starting attempt 1 of 1
[2024-03-11 04:34:02,721] {taskinstance.py:1097} INFO - 
--------------------------------------------------------------------------------
[2024-03-11 04:34:02,738] {taskinstance.py:1115} INFO - Executing <Task(PythonOperator): clean_answers> on 2024-03-11T04:33:59.355517+00:00
[2024-03-11 04:34:02,743] {standard_task_runner.py:52} INFO - Started process 4682 to run task
[2024-03-11 04:34:02,747] {standard_task_runner.py:76} INFO - Running: ['***', 'tasks', 'run', 'meeting_project492', 'clean_answers', '2024-03-11T04:33:59.355517+00:00', '--job-id', '627', '--pool', 'default_pool', '--raw', '--subdir', 'DAGS_FOLDER/first_dag.py', '--cfg-path', '/tmp/tmp4hhr3xyh', '--error-file', '/tmp/tmp4q877q4a']
[2024-03-11 04:34:02,749] {standard_task_runner.py:77} INFO - Job 627: Subtask clean_answers
[2024-03-11 04:34:02,797] {logging_mixin.py:109} INFO - Running <TaskInstance: meeting_project492.clean_answers 2024-03-11T04:33:59.355517+00:00 [running]> on host 5fe9ddfe21b9
[2024-03-11 04:34:02,856] {taskinstance.py:1254} INFO - Exporting the following env vars:
AIRFLOW_CTX_DAG_OWNER=***
AIRFLOW_CTX_DAG_ID=meeting_project492
AIRFLOW_CTX_TASK_ID=clean_answers
AIRFLOW_CTX_EXECUTION_DATE=2024-03-11T04:33:59.355517+00:00
AIRFLOW_CTX_DAG_RUN_ID=manual__2024-03-11T04:33:59.355517+00:00
[2024-03-11 04:34:02,881] {taskinstance.py:1463} ERROR - Task failed with exception
Traceback (most recent call last):
  File "/home/airflow/.local/lib/python3.6/site-packages/pandas/core/indexes/base.py", line 2898, in get_loc
    return self._engine.get_loc(casted_key)
  File "pandas/_libs/index.pyx", line 70, in pandas._libs.index.IndexEngine.get_loc
  File "pandas/_libs/index.pyx", line 101, in pandas._libs.index.IndexEngine.get_loc
  File "pandas/_libs/hashtable_class_helper.pxi", line 1675, in pandas._libs.hashtable.PyObjectHashTable.get_item
  File "pandas/_libs/hashtable_class_helper.pxi", line 1683, in pandas._libs.hashtable.PyObjectHashTable.get_item
KeyError: 'no_ans'

The above exception was the direct cause of the following exception:

Traceback (most recent call last):
  File "/home/airflow/.local/lib/python3.6/site-packages/airflow/models/taskinstance.py", line 1165, in _run_raw_task
    self._prepare_and_execute_task_with_callbacks(context, task)
  File "/home/airflow/.local/lib/python3.6/site-packages/airflow/models/taskinstance.py", line 1283, in _prepare_and_execute_task_with_callbacks
    result = self._execute_task(context, task_copy)
  File "/home/airflow/.local/lib/python3.6/site-packages/airflow/models/taskinstance.py", line 1313, in _execute_task
    result = task_copy.execute(context=context)
  File "/home/airflow/.local/lib/python3.6/site-packages/airflow/operators/python.py", line 150, in execute
    return_value = self.execute_callable()
  File "/home/airflow/.local/lib/python3.6/site-packages/airflow/operators/python.py", line 161, in execute_callable
    return self.python_callable(*self.op_args, **self.op_kwargs)
  File "/opt/airflow/dags/first_dag.py", line 73, in clean_answer
    df_sum['no_ans'] = df_sum['no_ans'].astype(int, errors = 'ignore')
  File "/home/airflow/.local/lib/python3.6/site-packages/pandas/core/frame.py", line 2906, in __getitem__
    indexer = self.columns.get_loc(key)
  File "/home/airflow/.local/lib/python3.6/site-packages/pandas/core/indexes/base.py", line 2900, in get_loc
    raise KeyError(key) from err
KeyError: 'no_ans'
[2024-03-11 04:34:02,884] {taskinstance.py:1513} INFO - Marking task as FAILED. dag_id=meeting_project492, task_id=clean_answers, execution_date=20240311T043359, start_date=20240311T043402, end_date=20240311T043402
[2024-03-11 04:34:02,918] {local_task_job.py:151} INFO - Task exited with return code 1
[2024-03-11 04:34:02,942] {local_task_job.py:261} INFO - 0 downstream tasks scheduled from follow-on schedule check
