[2024-03-01 14:55:43,704] {taskinstance.py:903} INFO - Dependencies all met for <TaskInstance: meeting.clean_meeting 2024-03-01T14:55:40.465292+00:00 [queued]>
[2024-03-01 14:55:43,719] {taskinstance.py:903} INFO - Dependencies all met for <TaskInstance: meeting.clean_meeting 2024-03-01T14:55:40.465292+00:00 [queued]>
[2024-03-01 14:55:43,720] {taskinstance.py:1095} INFO - 
--------------------------------------------------------------------------------
[2024-03-01 14:55:43,720] {taskinstance.py:1096} INFO - Starting attempt 1 of 1
[2024-03-01 14:55:43,720] {taskinstance.py:1097} INFO - 
--------------------------------------------------------------------------------
[2024-03-01 14:55:43,729] {taskinstance.py:1115} INFO - Executing <Task(PythonOperator): clean_meeting> on 2024-03-01T14:55:40.465292+00:00
[2024-03-01 14:55:43,733] {standard_task_runner.py:52} INFO - Started process 2309 to run task
[2024-03-01 14:55:43,735] {standard_task_runner.py:76} INFO - Running: ['***', 'tasks', 'run', 'meeting', 'clean_meeting', '2024-03-01T14:55:40.465292+00:00', '--job-id', '189', '--pool', 'default_pool', '--raw', '--subdir', 'DAGS_FOLDER/first_dag.py', '--cfg-path', '/tmp/tmppf0vtzbl', '--error-file', '/tmp/tmp7w_6d41g']
[2024-03-01 14:55:43,738] {standard_task_runner.py:77} INFO - Job 189: Subtask clean_meeting
[2024-03-01 14:55:43,771] {logging_mixin.py:109} INFO - Running <TaskInstance: meeting.clean_meeting 2024-03-01T14:55:40.465292+00:00 [running]> on host b272d77a87bd
[2024-03-01 14:55:43,825] {taskinstance.py:1254} INFO - Exporting the following env vars:
AIRFLOW_CTX_DAG_OWNER=***
AIRFLOW_CTX_DAG_ID=meeting
AIRFLOW_CTX_TASK_ID=clean_meeting
AIRFLOW_CTX_EXECUTION_DATE=2024-03-01T14:55:40.465292+00:00
AIRFLOW_CTX_DAG_RUN_ID=manual__2024-03-01T14:55:40.465292+00:00
[2024-03-01 14:55:43,859] {taskinstance.py:1463} ERROR - Task failed with exception
Traceback (most recent call last):
  File "/home/airflow/.local/lib/python3.6/site-packages/airflow/models/taskinstance.py", line 1165, in _run_raw_task
    self._prepare_and_execute_task_with_callbacks(context, task)
  File "/home/airflow/.local/lib/python3.6/site-packages/airflow/models/taskinstance.py", line 1283, in _prepare_and_execute_task_with_callbacks
    result = self._execute_task(context, task_copy)
  File "/home/airflow/.local/lib/python3.6/site-packages/airflow/models/taskinstance.py", line 1313, in _execute_task
    result = task_copy.execute(context=context)
  File "/home/airflow/.local/lib/python3.6/site-packages/airflow/operators/python.py", line 150, in execute
    return_value = self.execute_callable()
  File "/home/airflow/.local/lib/python3.6/site-packages/airflow/operators/python.py", line 161, in execute_callable
    return self.python_callable(*self.op_args, **self.op_kwargs)
  File "/opt/airflow/dags/first_dag.py", line 37, in clean_meet
    df["dow"] = df[['meetStartDate']].apply(lambda x: dt.datetime.strftime(x['meetStartDate'], '%A'), axis=1)
  File "/home/airflow/.local/lib/python3.6/site-packages/pandas/core/frame.py", line 7552, in apply
    return op.get_result()
  File "/home/airflow/.local/lib/python3.6/site-packages/pandas/core/apply.py", line 185, in get_result
    return self.apply_standard()
  File "/home/airflow/.local/lib/python3.6/site-packages/pandas/core/apply.py", line 276, in apply_standard
    results, res_index = self.apply_series_generator()
  File "/home/airflow/.local/lib/python3.6/site-packages/pandas/core/apply.py", line 305, in apply_series_generator
    results[i] = self.f(v)
  File "/opt/airflow/dags/first_dag.py", line 37, in <lambda>
    df["dow"] = df[['meetStartDate']].apply(lambda x: dt.datetime.strftime(x['meetStartDate'], '%A'), axis=1)
  File "pandas/_libs/tslibs/nattype.pyx", line 69, in pandas._libs.tslibs.nattype._make_error_func.f
ValueError: NaTType does not support timetuple
[2024-03-01 14:55:43,861] {taskinstance.py:1513} INFO - Marking task as FAILED. dag_id=meeting, task_id=clean_meeting, execution_date=20240301T145540, start_date=20240301T145543, end_date=20240301T145543
[2024-03-01 14:55:43,908] {local_task_job.py:151} INFO - Task exited with return code 1
[2024-03-01 14:55:43,943] {local_task_job.py:261} INFO - 0 downstream tasks scheduled from follow-on schedule check
