[2024-03-11 04:15:00,787] {taskinstance.py:903} INFO - Dependencies all met for <TaskInstance: meeting_project492.merge_data 2024-03-11T04:14:55.854646+00:00 [queued]>
[2024-03-11 04:15:00,802] {taskinstance.py:903} INFO - Dependencies all met for <TaskInstance: meeting_project492.merge_data 2024-03-11T04:14:55.854646+00:00 [queued]>
[2024-03-11 04:15:00,802] {taskinstance.py:1095} INFO - 
--------------------------------------------------------------------------------
[2024-03-11 04:15:00,802] {taskinstance.py:1096} INFO - Starting attempt 1 of 1
[2024-03-11 04:15:00,802] {taskinstance.py:1097} INFO - 
--------------------------------------------------------------------------------
[2024-03-11 04:15:00,810] {taskinstance.py:1115} INFO - Executing <Task(PythonOperator): merge_data> on 2024-03-11T04:14:55.854646+00:00
[2024-03-11 04:15:00,815] {standard_task_runner.py:52} INFO - Started process 1293 to run task
[2024-03-11 04:15:00,819] {standard_task_runner.py:76} INFO - Running: ['***', 'tasks', 'run', 'meeting_project492', 'merge_data', '2024-03-11T04:14:55.854646+00:00', '--job-id', '568', '--pool', 'default_pool', '--raw', '--subdir', 'DAGS_FOLDER/first_dag.py', '--cfg-path', '/tmp/tmp0eu1_fy7', '--error-file', '/tmp/tmpzif4zdto']
[2024-03-11 04:15:00,821] {standard_task_runner.py:77} INFO - Job 568: Subtask merge_data
[2024-03-11 04:15:00,856] {logging_mixin.py:109} INFO - Running <TaskInstance: meeting_project492.merge_data 2024-03-11T04:14:55.854646+00:00 [running]> on host 76207e23fd35
[2024-03-11 04:15:00,905] {taskinstance.py:1254} INFO - Exporting the following env vars:
AIRFLOW_CTX_DAG_OWNER=***
AIRFLOW_CTX_DAG_ID=meeting_project492
AIRFLOW_CTX_TASK_ID=merge_data
AIRFLOW_CTX_EXECUTION_DATE=2024-03-11T04:14:55.854646+00:00
AIRFLOW_CTX_DAG_RUN_ID=manual__2024-03-11T04:14:55.854646+00:00
[2024-03-11 04:15:00,935] {taskinstance.py:1463} ERROR - Task failed with exception
Traceback (most recent call last):
  File "/home/airflow/.local/lib/python3.6/site-packages/airflow/models/taskinstance.py", line 1165, in _run_raw_task
    self._prepare_and_execute_task_with_callbacks(context, task)
  File "/home/airflow/.local/lib/python3.6/site-packages/airflow/models/taskinstance.py", line 1283, in _prepare_and_execute_task_with_callbacks
    result = self._execute_task(context, task_copy)
  File "/home/airflow/.local/lib/python3.6/site-packages/airflow/models/taskinstance.py", line 1313, in _execute_task
    result = task_copy.execute(context=context)
  File "/home/airflow/.local/lib/python3.6/site-packages/airflow/operators/python.py", line 150, in execute
    return_value = self.execute_callable()
  File "/home/airflow/.local/lib/python3.6/site-packages/airflow/operators/python.py", line 161, in execute_callable
    return self.python_callable(*self.op_args, **self.op_kwargs)
  File "/opt/airflow/dags/first_dag.py", line 107, in merge_data
    df_meet_fol_ans_com_obj['no_ans'] = df_meet_fol_ans_com_obj['no_ans'].astype(int, errors = 'raise')
  File "/home/airflow/.local/lib/python3.6/site-packages/pandas/core/generic.py", line 5548, in astype
    new_data = self._mgr.astype(dtype=dtype, copy=copy, errors=errors,)
  File "/home/airflow/.local/lib/python3.6/site-packages/pandas/core/internals/managers.py", line 604, in astype
    return self.apply("astype", dtype=dtype, copy=copy, errors=errors)
  File "/home/airflow/.local/lib/python3.6/site-packages/pandas/core/internals/managers.py", line 409, in apply
    applied = getattr(b, f)(**kwargs)
  File "/home/airflow/.local/lib/python3.6/site-packages/pandas/core/internals/blocks.py", line 595, in astype
    values = astype_nansafe(vals1d, dtype, copy=True)
  File "/home/airflow/.local/lib/python3.6/site-packages/pandas/core/dtypes/cast.py", line 968, in astype_nansafe
    raise ValueError("Cannot convert non-finite values (NA or inf) to integer")
ValueError: Cannot convert non-finite values (NA or inf) to integer
[2024-03-11 04:15:00,938] {taskinstance.py:1513} INFO - Marking task as FAILED. dag_id=meeting_project492, task_id=merge_data, execution_date=20240311T041455, start_date=20240311T041500, end_date=20240311T041500
[2024-03-11 04:15:00,991] {local_task_job.py:151} INFO - Task exited with return code 1
[2024-03-11 04:15:01,011] {local_task_job.py:261} INFO - 0 downstream tasks scheduled from follow-on schedule check
