[2024-03-28 18:16:01,133] {taskinstance.py:903} INFO - Dependencies all met for <TaskInstance: meeting_project492.clean_meeting 2024-03-28T17:00:00+00:00 [queued]>
[2024-03-28 18:16:01,157] {taskinstance.py:903} INFO - Dependencies all met for <TaskInstance: meeting_project492.clean_meeting 2024-03-28T17:00:00+00:00 [queued]>
[2024-03-28 18:16:01,157] {taskinstance.py:1095} INFO - 
--------------------------------------------------------------------------------
[2024-03-28 18:16:01,157] {taskinstance.py:1096} INFO - Starting attempt 1 of 1
[2024-03-28 18:16:01,158] {taskinstance.py:1097} INFO - 
--------------------------------------------------------------------------------
[2024-03-28 18:16:01,191] {taskinstance.py:1115} INFO - Executing <Task(PythonOperator): clean_meeting> on 2024-03-28T17:00:00+00:00
[2024-03-28 18:16:01,200] {standard_task_runner.py:52} INFO - Started process 652 to run task
[2024-03-28 18:16:01,205] {standard_task_runner.py:76} INFO - Running: ['***', 'tasks', 'run', 'meeting_project492', 'clean_meeting', '2024-03-28T17:00:00+00:00', '--job-id', '718', '--pool', 'default_pool', '--raw', '--subdir', 'DAGS_FOLDER/first_dag.py', '--cfg-path', '/tmp/tmpipnjr76u', '--error-file', '/tmp/tmptx55fb36']
[2024-03-28 18:16:01,211] {standard_task_runner.py:77} INFO - Job 718: Subtask clean_meeting
[2024-03-28 18:16:01,285] {logging_mixin.py:109} INFO - Running <TaskInstance: meeting_project492.clean_meeting 2024-03-28T17:00:00+00:00 [running]> on host 322f1435f697
[2024-03-28 18:16:01,372] {taskinstance.py:1254} INFO - Exporting the following env vars:
AIRFLOW_CTX_DAG_OWNER=***
AIRFLOW_CTX_DAG_ID=meeting_project492
AIRFLOW_CTX_TASK_ID=clean_meeting
AIRFLOW_CTX_EXECUTION_DATE=2024-03-28T17:00:00+00:00
AIRFLOW_CTX_DAG_RUN_ID=scheduled__2024-03-28T17:00:00+00:00
[2024-03-28 18:16:01,390] {taskinstance.py:1463} ERROR - Task failed with exception
Traceback (most recent call last):
  File "/home/airflow/.local/lib/python3.6/site-packages/pandas/core/indexes/base.py", line 2898, in get_loc
    return self._engine.get_loc(casted_key)
  File "pandas/_libs/index.pyx", line 70, in pandas._libs.index.IndexEngine.get_loc
  File "pandas/_libs/index.pyx", line 101, in pandas._libs.index.IndexEngine.get_loc
  File "pandas/_libs/hashtable_class_helper.pxi", line 1675, in pandas._libs.hashtable.PyObjectHashTable.get_item
  File "pandas/_libs/hashtable_class_helper.pxi", line 1683, in pandas._libs.hashtable.PyObjectHashTable.get_item
KeyError: 'meetTagId'

The above exception was the direct cause of the following exception:

Traceback (most recent call last):
  File "/home/airflow/.local/lib/python3.6/site-packages/airflow/models/taskinstance.py", line 1165, in _run_raw_task
    self._prepare_and_execute_task_with_callbacks(context, task)
  File "/home/airflow/.local/lib/python3.6/site-packages/airflow/models/taskinstance.py", line 1283, in _prepare_and_execute_task_with_callbacks
    result = self._execute_task(context, task_copy)
  File "/home/airflow/.local/lib/python3.6/site-packages/airflow/models/taskinstance.py", line 1313, in _execute_task
    result = task_copy.execute(context=context)
  File "/home/airflow/.local/lib/python3.6/site-packages/airflow/operators/python.py", line 150, in execute
    return_value = self.execute_callable()
  File "/home/airflow/.local/lib/python3.6/site-packages/airflow/operators/python.py", line 161, in execute_callable
    return self.python_callable(*self.op_args, **self.op_kwargs)
  File "/opt/airflow/dags/first_dag.py", line 46, in clean_meet
    df['meetTagId'] = df['meetTagId'].replace(meet_type)
  File "/home/airflow/.local/lib/python3.6/site-packages/pandas/core/frame.py", line 2906, in __getitem__
    indexer = self.columns.get_loc(key)
  File "/home/airflow/.local/lib/python3.6/site-packages/pandas/core/indexes/base.py", line 2900, in get_loc
    raise KeyError(key) from err
KeyError: 'meetTagId'
[2024-03-28 18:16:01,394] {taskinstance.py:1513} INFO - Marking task as FAILED. dag_id=meeting_project492, task_id=clean_meeting, execution_date=20240328T170000, start_date=20240328T181601, end_date=20240328T181601
[2024-03-28 18:16:01,456] {local_task_job.py:151} INFO - Task exited with return code 1
[2024-03-28 18:16:01,488] {local_task_job.py:261} INFO - 0 downstream tasks scheduled from follow-on schedule check
