[2024-03-10 16:16:02,489] {taskinstance.py:903} INFO - Dependencies all met for <TaskInstance: meeting_project492.clean_comment 2024-03-10T15:00:00+00:00 [queued]>
[2024-03-10 16:16:02,513] {taskinstance.py:903} INFO - Dependencies all met for <TaskInstance: meeting_project492.clean_comment 2024-03-10T15:00:00+00:00 [queued]>
[2024-03-10 16:16:02,513] {taskinstance.py:1095} INFO - 
--------------------------------------------------------------------------------
[2024-03-10 16:16:02,513] {taskinstance.py:1096} INFO - Starting attempt 1 of 1
[2024-03-10 16:16:02,513] {taskinstance.py:1097} INFO - 
--------------------------------------------------------------------------------
[2024-03-10 16:16:02,546] {taskinstance.py:1115} INFO - Executing <Task(PythonOperator): clean_comment> on 2024-03-10T15:00:00+00:00
[2024-03-10 16:16:02,559] {standard_task_runner.py:52} INFO - Started process 592 to run task
[2024-03-10 16:16:02,565] {standard_task_runner.py:76} INFO - Running: ['***', 'tasks', 'run', 'meeting_project492', 'clean_comment', '2024-03-10T15:00:00+00:00', '--job-id', '402', '--pool', 'default_pool', '--raw', '--subdir', 'DAGS_FOLDER/first_dag.py', '--cfg-path', '/tmp/tmp10w5rdo0', '--error-file', '/tmp/tmpw_zqbiqe']
[2024-03-10 16:16:02,569] {standard_task_runner.py:77} INFO - Job 402: Subtask clean_comment
[2024-03-10 16:16:02,634] {logging_mixin.py:109} INFO - Running <TaskInstance: meeting_project492.clean_comment 2024-03-10T15:00:00+00:00 [running]> on host 6053b7d19b63
[2024-03-10 16:16:02,743] {taskinstance.py:1254} INFO - Exporting the following env vars:
AIRFLOW_CTX_DAG_OWNER=***
AIRFLOW_CTX_DAG_ID=meeting_project492
AIRFLOW_CTX_TASK_ID=clean_comment
AIRFLOW_CTX_EXECUTION_DATE=2024-03-10T15:00:00+00:00
AIRFLOW_CTX_DAG_RUN_ID=scheduled__2024-03-10T15:00:00+00:00
[2024-03-10 16:16:02,771] {taskinstance.py:1463} ERROR - Task failed with exception
Traceback (most recent call last):
  File "/home/airflow/.local/lib/python3.6/site-packages/airflow/models/taskinstance.py", line 1165, in _run_raw_task
    self._prepare_and_execute_task_with_callbacks(context, task)
  File "/home/airflow/.local/lib/python3.6/site-packages/airflow/models/taskinstance.py", line 1283, in _prepare_and_execute_task_with_callbacks
    result = self._execute_task(context, task_copy)
  File "/home/airflow/.local/lib/python3.6/site-packages/airflow/models/taskinstance.py", line 1313, in _execute_task
    result = task_copy.execute(context=context)
  File "/home/airflow/.local/lib/python3.6/site-packages/airflow/operators/python.py", line 150, in execute
    return_value = self.execute_callable()
  File "/home/airflow/.local/lib/python3.6/site-packages/airflow/operators/python.py", line 161, in execute_callable
    return self.python_callable(*self.op_args, **self.op_kwargs)
  File "/opt/airflow/dags/first_dag.py", line 79, in clean_com
    df = df[['meetId', 'comment', 'senId']].rename(columns={'senId': 'sentiment'})
  File "/home/airflow/.local/lib/python3.6/site-packages/pandas/core/frame.py", line 2912, in __getitem__
    indexer = self.loc._get_listlike_indexer(key, axis=1, raise_missing=True)[1]
  File "/home/airflow/.local/lib/python3.6/site-packages/pandas/core/indexing.py", line 1254, in _get_listlike_indexer
    self._validate_read_indexer(keyarr, indexer, axis, raise_missing=raise_missing)
  File "/home/airflow/.local/lib/python3.6/site-packages/pandas/core/indexing.py", line 1304, in _validate_read_indexer
    raise KeyError(f"{not_found} not in index")
KeyError: "['senId'] not in index"
[2024-03-10 16:16:02,775] {taskinstance.py:1513} INFO - Marking task as FAILED. dag_id=meeting_project492, task_id=clean_comment, execution_date=20240310T150000, start_date=20240310T161602, end_date=20240310T161602
[2024-03-10 16:16:02,819] {local_task_job.py:151} INFO - Task exited with return code 1
[2024-03-10 16:16:02,867] {local_task_job.py:261} INFO - 0 downstream tasks scheduled from follow-on schedule check
