[2023-12-03 14:39:32,730] {taskinstance.py:903} INFO - Dependencies all met for <TaskInstance: meeting.merge_data 2023-12-03T14:39:27.527825+00:00 [queued]>
[2023-12-03 14:39:32,739] {taskinstance.py:903} INFO - Dependencies all met for <TaskInstance: meeting.merge_data 2023-12-03T14:39:27.527825+00:00 [queued]>
[2023-12-03 14:39:32,740] {taskinstance.py:1095} INFO - 
--------------------------------------------------------------------------------
[2023-12-03 14:39:32,740] {taskinstance.py:1096} INFO - Starting attempt 1 of 1
[2023-12-03 14:39:32,740] {taskinstance.py:1097} INFO - 
--------------------------------------------------------------------------------
[2023-12-03 14:39:32,754] {taskinstance.py:1115} INFO - Executing <Task(PythonOperator): merge_data> on 2023-12-03T14:39:27.527825+00:00
[2023-12-03 14:39:32,757] {standard_task_runner.py:52} INFO - Started process 6264 to run task
[2023-12-03 14:39:32,761] {standard_task_runner.py:76} INFO - Running: ['***', 'tasks', 'run', 'meeting', 'merge_data', '2023-12-03T14:39:27.527825+00:00', '--job-id', '71', '--pool', 'default_pool', '--raw', '--subdir', 'DAGS_FOLDER/first_dag.py', '--cfg-path', '/tmp/tmpk6bzfb4t', '--error-file', '/tmp/tmpalcxafqe']
[2023-12-03 14:39:32,763] {standard_task_runner.py:77} INFO - Job 71: Subtask merge_data
[2023-12-03 14:39:32,796] {logging_mixin.py:109} INFO - Running <TaskInstance: meeting.merge_data 2023-12-03T14:39:27.527825+00:00 [running]> on host 9d53e6732d94
[2023-12-03 14:39:32,844] {taskinstance.py:1254} INFO - Exporting the following env vars:
AIRFLOW_CTX_DAG_OWNER=***
AIRFLOW_CTX_DAG_ID=meeting
AIRFLOW_CTX_TASK_ID=merge_data
AIRFLOW_CTX_EXECUTION_DATE=2023-12-03T14:39:27.527825+00:00
AIRFLOW_CTX_DAG_RUN_ID=manual__2023-12-03T14:39:27.527825+00:00
[2023-12-03 14:39:32,855] {taskinstance.py:1463} ERROR - Task failed with exception
Traceback (most recent call last):
  File "/home/airflow/.local/lib/python3.6/site-packages/airflow/models/taskinstance.py", line 1165, in _run_raw_task
    self._prepare_and_execute_task_with_callbacks(context, task)
  File "/home/airflow/.local/lib/python3.6/site-packages/airflow/models/taskinstance.py", line 1283, in _prepare_and_execute_task_with_callbacks
    result = self._execute_task(context, task_copy)
  File "/home/airflow/.local/lib/python3.6/site-packages/airflow/models/taskinstance.py", line 1313, in _execute_task
    result = task_copy.execute(context=context)
  File "/home/airflow/.local/lib/python3.6/site-packages/airflow/operators/python.py", line 150, in execute
    return_value = self.execute_callable()
  File "/home/airflow/.local/lib/python3.6/site-packages/airflow/operators/python.py", line 161, in execute_callable
    return self.python_callable(*self.op_args, **self.op_kwargs)
  File "/opt/airflow/dags/first_dag.py", line 56, in merge_data
    df_summary = df_sum_cpm.merge(df_meet, on = 'meetId', how = 'right')
  File "/home/airflow/.local/lib/python3.6/site-packages/pandas/core/frame.py", line 7963, in merge
    validate=validate,
  File "/home/airflow/.local/lib/python3.6/site-packages/pandas/core/reshape/merge.py", line 87, in merge
    validate=validate,
  File "/home/airflow/.local/lib/python3.6/site-packages/pandas/core/reshape/merge.py", line 652, in __init__
    ) = self._get_merge_keys()
  File "/home/airflow/.local/lib/python3.6/site-packages/pandas/core/reshape/merge.py", line 1018, in _get_merge_keys
    left_keys.append(left._get_label_or_level_values(lk))
  File "/home/airflow/.local/lib/python3.6/site-packages/pandas/core/generic.py", line 1563, in _get_label_or_level_values
    raise KeyError(key)
KeyError: 'meetId'
[2023-12-03 14:39:32,861] {taskinstance.py:1513} INFO - Marking task as FAILED. dag_id=meeting, task_id=merge_data, execution_date=20231203T143927, start_date=20231203T143932, end_date=20231203T143932
[2023-12-03 14:39:32,892] {local_task_job.py:151} INFO - Task exited with return code 1
[2023-12-03 14:39:32,914] {local_task_job.py:261} INFO - 0 downstream tasks scheduled from follow-on schedule check
