[2024-03-05 10:17:35,128] {taskinstance.py:903} INFO - Dependencies all met for <TaskInstance: meeting_project.clean_meeting 2024-03-05T10:17:31.061461+00:00 [queued]>
[2024-03-05 10:17:35,144] {taskinstance.py:903} INFO - Dependencies all met for <TaskInstance: meeting_project.clean_meeting 2024-03-05T10:17:31.061461+00:00 [queued]>
[2024-03-05 10:17:35,144] {taskinstance.py:1095} INFO - 
--------------------------------------------------------------------------------
[2024-03-05 10:17:35,144] {taskinstance.py:1096} INFO - Starting attempt 1 of 1
[2024-03-05 10:17:35,144] {taskinstance.py:1097} INFO - 
--------------------------------------------------------------------------------
[2024-03-05 10:17:35,153] {taskinstance.py:1115} INFO - Executing <Task(PythonOperator): clean_meeting> on 2024-03-05T10:17:31.061461+00:00
[2024-03-05 10:17:35,157] {standard_task_runner.py:52} INFO - Started process 3535 to run task
[2024-03-05 10:17:35,160] {standard_task_runner.py:76} INFO - Running: ['***', 'tasks', 'run', 'meeting_project', 'clean_meeting', '2024-03-05T10:17:31.061461+00:00', '--job-id', '265', '--pool', 'default_pool', '--raw', '--subdir', 'DAGS_FOLDER/first_dag.py', '--cfg-path', '/tmp/tmp5zxnxluq', '--error-file', '/tmp/tmplb8jfvld']
[2024-03-05 10:17:35,162] {standard_task_runner.py:77} INFO - Job 265: Subtask clean_meeting
[2024-03-05 10:17:35,197] {logging_mixin.py:109} INFO - Running <TaskInstance: meeting_project.clean_meeting 2024-03-05T10:17:31.061461+00:00 [running]> on host 4622d7b8f726
[2024-03-05 10:17:35,249] {taskinstance.py:1254} INFO - Exporting the following env vars:
AIRFLOW_CTX_DAG_OWNER=***
AIRFLOW_CTX_DAG_ID=meeting_project
AIRFLOW_CTX_TASK_ID=clean_meeting
AIRFLOW_CTX_EXECUTION_DATE=2024-03-05T10:17:31.061461+00:00
AIRFLOW_CTX_DAG_RUN_ID=manual__2024-03-05T10:17:31.061461+00:00
[2024-03-05 10:17:35,292] {taskinstance.py:1463} ERROR - Task failed with exception
Traceback (most recent call last):
  File "/home/airflow/.local/lib/python3.6/site-packages/airflow/models/taskinstance.py", line 1165, in _run_raw_task
    self._prepare_and_execute_task_with_callbacks(context, task)
  File "/home/airflow/.local/lib/python3.6/site-packages/airflow/models/taskinstance.py", line 1283, in _prepare_and_execute_task_with_callbacks
    result = self._execute_task(context, task_copy)
  File "/home/airflow/.local/lib/python3.6/site-packages/airflow/models/taskinstance.py", line 1313, in _execute_task
    result = task_copy.execute(context=context)
  File "/home/airflow/.local/lib/python3.6/site-packages/airflow/operators/python.py", line 150, in execute
    return_value = self.execute_callable()
  File "/home/airflow/.local/lib/python3.6/site-packages/airflow/operators/python.py", line 161, in execute_callable
    return self.python_callable(*self.op_args, **self.op_kwargs)
  File "/opt/airflow/dags/first_dag.py", line 55, in clean_meet
    df_meet = df[["folderId", "folderName", "meetId", "meetName", "minusTime", "meetStartDate","dow", "meetTagId"]]
  File "/home/airflow/.local/lib/python3.6/site-packages/pandas/core/frame.py", line 2912, in __getitem__
    indexer = self.loc._get_listlike_indexer(key, axis=1, raise_missing=True)[1]
  File "/home/airflow/.local/lib/python3.6/site-packages/pandas/core/indexing.py", line 1254, in _get_listlike_indexer
    self._validate_read_indexer(keyarr, indexer, axis, raise_missing=raise_missing)
  File "/home/airflow/.local/lib/python3.6/site-packages/pandas/core/indexing.py", line 1304, in _validate_read_indexer
    raise KeyError(f"{not_found} not in index")
KeyError: "['folderName'] not in index"
[2024-03-05 10:17:35,295] {taskinstance.py:1513} INFO - Marking task as FAILED. dag_id=meeting_project, task_id=clean_meeting, execution_date=20240305T101731, start_date=20240305T101735, end_date=20240305T101735
[2024-03-05 10:17:35,332] {local_task_job.py:151} INFO - Task exited with return code 1
[2024-03-05 10:17:35,356] {local_task_job.py:261} INFO - 0 downstream tasks scheduled from follow-on schedule check
