[2024-03-01 09:03:51,990] {taskinstance.py:903} INFO - Dependencies all met for <TaskInstance: meeting.fetch_meeting 2024-03-01T09:03:50.849526+00:00 [queued]>
[2024-03-01 09:03:52,006] {taskinstance.py:903} INFO - Dependencies all met for <TaskInstance: meeting.fetch_meeting 2024-03-01T09:03:50.849526+00:00 [queued]>
[2024-03-01 09:03:52,006] {taskinstance.py:1095} INFO - 
--------------------------------------------------------------------------------
[2024-03-01 09:03:52,006] {taskinstance.py:1096} INFO - Starting attempt 1 of 1
[2024-03-01 09:03:52,006] {taskinstance.py:1097} INFO - 
--------------------------------------------------------------------------------
[2024-03-01 09:03:52,015] {taskinstance.py:1115} INFO - Executing <Task(PythonOperator): fetch_meeting> on 2024-03-01T09:03:50.849526+00:00
[2024-03-01 09:03:52,020] {standard_task_runner.py:52} INFO - Started process 826 to run task
[2024-03-01 09:03:52,023] {standard_task_runner.py:76} INFO - Running: ['***', 'tasks', 'run', 'meeting', 'fetch_meeting', '2024-03-01T09:03:50.849526+00:00', '--job-id', '162', '--pool', 'default_pool', '--raw', '--subdir', 'DAGS_FOLDER/first_dag.py', '--cfg-path', '/tmp/tmp3wku4g0s', '--error-file', '/tmp/tmp85uyu3qj']
[2024-03-01 09:03:52,025] {standard_task_runner.py:77} INFO - Job 162: Subtask fetch_meeting
[2024-03-01 09:03:52,060] {logging_mixin.py:109} INFO - Running <TaskInstance: meeting.fetch_meeting 2024-03-01T09:03:50.849526+00:00 [running]> on host 9deaaf5c1807
[2024-03-01 09:03:52,108] {taskinstance.py:1254} INFO - Exporting the following env vars:
AIRFLOW_CTX_DAG_OWNER=***
AIRFLOW_CTX_DAG_ID=meeting
AIRFLOW_CTX_TASK_ID=fetch_meeting
AIRFLOW_CTX_EXECUTION_DATE=2024-03-01T09:03:50.849526+00:00
AIRFLOW_CTX_DAG_RUN_ID=manual__2024-03-01T09:03:50.849526+00:00
[2024-03-01 09:03:52,127] {taskinstance.py:1463} ERROR - Task failed with exception
Traceback (most recent call last):
  File "/home/airflow/.local/lib/python3.6/site-packages/sqlalchemy/engine/base.py", line 2336, in _wrap_pool_connect
    return fn()
  File "/home/airflow/.local/lib/python3.6/site-packages/sqlalchemy/pool/base.py", line 364, in connect
    return _ConnectionFairy._checkout(self)
  File "/home/airflow/.local/lib/python3.6/site-packages/sqlalchemy/pool/base.py", line 778, in _checkout
    fairy = _ConnectionRecord.checkout(pool)
  File "/home/airflow/.local/lib/python3.6/site-packages/sqlalchemy/pool/base.py", line 495, in checkout
    rec = pool._do_get()
  File "/home/airflow/.local/lib/python3.6/site-packages/sqlalchemy/pool/impl.py", line 140, in _do_get
    self._dec_overflow()
  File "/home/airflow/.local/lib/python3.6/site-packages/sqlalchemy/util/langhelpers.py", line 70, in __exit__
    with_traceback=exc_tb,
  File "/home/airflow/.local/lib/python3.6/site-packages/sqlalchemy/util/compat.py", line 182, in raise_
    raise exception
  File "/home/airflow/.local/lib/python3.6/site-packages/sqlalchemy/pool/impl.py", line 137, in _do_get
    return self._create_connection()
  File "/home/airflow/.local/lib/python3.6/site-packages/sqlalchemy/pool/base.py", line 309, in _create_connection
    return _ConnectionRecord(self)
  File "/home/airflow/.local/lib/python3.6/site-packages/sqlalchemy/pool/base.py", line 440, in __init__
    self.__connect(first_connect_check=True)
  File "/home/airflow/.local/lib/python3.6/site-packages/sqlalchemy/pool/base.py", line 661, in __connect
    pool.logger.debug("Error on connect(): %s", e)
  File "/home/airflow/.local/lib/python3.6/site-packages/sqlalchemy/util/langhelpers.py", line 70, in __exit__
    with_traceback=exc_tb,
  File "/home/airflow/.local/lib/python3.6/site-packages/sqlalchemy/util/compat.py", line 182, in raise_
    raise exception
  File "/home/airflow/.local/lib/python3.6/site-packages/sqlalchemy/pool/base.py", line 656, in __connect
    connection = pool._invoke_creator(self)
  File "/home/airflow/.local/lib/python3.6/site-packages/sqlalchemy/engine/strategies.py", line 114, in connect
    return dialect.connect(*cargs, **cparams)
  File "/home/airflow/.local/lib/python3.6/site-packages/sqlalchemy/engine/default.py", line 508, in connect
    return self.dbapi.connect(*cargs, **cparams)
  File "/home/airflow/.local/lib/python3.6/site-packages/psycopg2/__init__.py", line 122, in connect
    conn = _connect(dsn, connection_factory=connection_factory, **kwasync)
psycopg2.OperationalError: could not connect to server: Cannot assign requested address
	Is the server running on host "db.oymrhotncbnylwsroxra.supabase.co" (2406:da18:243:7404:c89c:992:ccd8:5e5e) and accepting
	TCP/IP connections on port 5432?


The above exception was the direct cause of the following exception:

Traceback (most recent call last):
  File "/home/airflow/.local/lib/python3.6/site-packages/airflow/models/taskinstance.py", line 1165, in _run_raw_task
    self._prepare_and_execute_task_with_callbacks(context, task)
  File "/home/airflow/.local/lib/python3.6/site-packages/airflow/models/taskinstance.py", line 1283, in _prepare_and_execute_task_with_callbacks
    result = self._execute_task(context, task_copy)
  File "/home/airflow/.local/lib/python3.6/site-packages/airflow/models/taskinstance.py", line 1313, in _execute_task
    result = task_copy.execute(context=context)
  File "/home/airflow/.local/lib/python3.6/site-packages/airflow/operators/python.py", line 150, in execute
    return_value = self.execute_callable()
  File "/home/airflow/.local/lib/python3.6/site-packages/airflow/operators/python.py", line 161, in execute_callable
    return self.python_callable(*self.op_args, **self.op_kwargs)
  File "/opt/airflow/dags/first_dag.py", line 15, in fetch_data
    df = pd.read_sql(f'select * from {table};', con)
  File "/home/airflow/.local/lib/python3.6/site-packages/pandas/io/sql.py", line 515, in read_sql
    chunksize=chunksize,
  File "/home/airflow/.local/lib/python3.6/site-packages/pandas/io/sql.py", line 1295, in read_query
    result = self.execute(*args)
  File "/home/airflow/.local/lib/python3.6/site-packages/pandas/io/sql.py", line 1162, in execute
    *args, **kwargs
  File "/home/airflow/.local/lib/python3.6/site-packages/sqlalchemy/engine/base.py", line 2234, in execute
    connection = self._contextual_connect(close_with_result=True)
  File "/home/airflow/.local/lib/python3.6/site-packages/sqlalchemy/engine/base.py", line 2302, in _contextual_connect
    self._wrap_pool_connect(self.pool.connect, None),
  File "/home/airflow/.local/lib/python3.6/site-packages/sqlalchemy/engine/base.py", line 2340, in _wrap_pool_connect
    e, dialect, self
  File "/home/airflow/.local/lib/python3.6/site-packages/sqlalchemy/engine/base.py", line 1584, in _handle_dbapi_exception_noconnection
    sqlalchemy_exception, with_traceback=exc_info[2], from_=e
  File "/home/airflow/.local/lib/python3.6/site-packages/sqlalchemy/util/compat.py", line 182, in raise_
    raise exception
  File "/home/airflow/.local/lib/python3.6/site-packages/sqlalchemy/engine/base.py", line 2336, in _wrap_pool_connect
    return fn()
  File "/home/airflow/.local/lib/python3.6/site-packages/sqlalchemy/pool/base.py", line 364, in connect
    return _ConnectionFairy._checkout(self)
  File "/home/airflow/.local/lib/python3.6/site-packages/sqlalchemy/pool/base.py", line 778, in _checkout
    fairy = _ConnectionRecord.checkout(pool)
  File "/home/airflow/.local/lib/python3.6/site-packages/sqlalchemy/pool/base.py", line 495, in checkout
    rec = pool._do_get()
  File "/home/airflow/.local/lib/python3.6/site-packages/sqlalchemy/pool/impl.py", line 140, in _do_get
    self._dec_overflow()
  File "/home/airflow/.local/lib/python3.6/site-packages/sqlalchemy/util/langhelpers.py", line 70, in __exit__
    with_traceback=exc_tb,
  File "/home/airflow/.local/lib/python3.6/site-packages/sqlalchemy/util/compat.py", line 182, in raise_
    raise exception
  File "/home/airflow/.local/lib/python3.6/site-packages/sqlalchemy/pool/impl.py", line 137, in _do_get
    return self._create_connection()
  File "/home/airflow/.local/lib/python3.6/site-packages/sqlalchemy/pool/base.py", line 309, in _create_connection
    return _ConnectionRecord(self)
  File "/home/airflow/.local/lib/python3.6/site-packages/sqlalchemy/pool/base.py", line 440, in __init__
    self.__connect(first_connect_check=True)
  File "/home/airflow/.local/lib/python3.6/site-packages/sqlalchemy/pool/base.py", line 661, in __connect
    pool.logger.debug("Error on connect(): %s", e)
  File "/home/airflow/.local/lib/python3.6/site-packages/sqlalchemy/util/langhelpers.py", line 70, in __exit__
    with_traceback=exc_tb,
  File "/home/airflow/.local/lib/python3.6/site-packages/sqlalchemy/util/compat.py", line 182, in raise_
    raise exception
  File "/home/airflow/.local/lib/python3.6/site-packages/sqlalchemy/pool/base.py", line 656, in __connect
    connection = pool._invoke_creator(self)
  File "/home/airflow/.local/lib/python3.6/site-packages/sqlalchemy/engine/strategies.py", line 114, in connect
    return dialect.connect(*cargs, **cparams)
  File "/home/airflow/.local/lib/python3.6/site-packages/sqlalchemy/engine/default.py", line 508, in connect
    return self.dbapi.connect(*cargs, **cparams)
  File "/home/airflow/.local/lib/python3.6/site-packages/psycopg2/__init__.py", line 122, in connect
    conn = _connect(dsn, connection_factory=connection_factory, **kwasync)
sqlalchemy.exc.OperationalError: (psycopg2.OperationalError) could not connect to server: Cannot assign requested address
	Is the server running on host "db.oymrhotncbnylwsroxra.supabase.co" (2406:da18:243:7404:c89c:992:ccd8:5e5e) and accepting
	TCP/IP connections on port 5432?

(Background on this error at: http://sqlalche.me/e/13/e3q8)
[2024-03-01 09:03:52,130] {taskinstance.py:1513} INFO - Marking task as FAILED. dag_id=meeting, task_id=fetch_meeting, execution_date=20240301T090350, start_date=20240301T090351, end_date=20240301T090352
[2024-03-01 09:03:52,155] {local_task_job.py:151} INFO - Task exited with return code 1
[2024-03-01 09:03:52,194] {local_task_job.py:261} INFO - 0 downstream tasks scheduled from follow-on schedule check
