[2024-03-09 03:00:08,851] {taskinstance.py:903} INFO - Dependencies all met for <TaskInstance: meeting_project492.merge_data 2024-03-09T02:00:00+00:00 [queued]>
[2024-03-09 03:00:08,861] {taskinstance.py:903} INFO - Dependencies all met for <TaskInstance: meeting_project492.merge_data 2024-03-09T02:00:00+00:00 [queued]>
[2024-03-09 03:00:08,861] {taskinstance.py:1095} INFO - 
--------------------------------------------------------------------------------
[2024-03-09 03:00:08,862] {taskinstance.py:1096} INFO - Starting attempt 1 of 1
[2024-03-09 03:00:08,862] {taskinstance.py:1097} INFO - 
--------------------------------------------------------------------------------
[2024-03-09 03:00:08,876] {taskinstance.py:1115} INFO - Executing <Task(PythonOperator): merge_data> on 2024-03-09T02:00:00+00:00
[2024-03-09 03:00:08,881] {standard_task_runner.py:52} INFO - Started process 2055 to run task
[2024-03-09 03:00:08,884] {standard_task_runner.py:76} INFO - Running: ['***', 'tasks', 'run', 'meeting_project492', 'merge_data', '2024-03-09T02:00:00+00:00', '--job-id', '357', '--pool', 'default_pool', '--raw', '--subdir', 'DAGS_FOLDER/first_dag.py', '--cfg-path', '/tmp/tmp1ia4fe00', '--error-file', '/tmp/tmpczqwy9r6']
[2024-03-09 03:00:08,886] {standard_task_runner.py:77} INFO - Job 357: Subtask merge_data
[2024-03-09 03:00:08,922] {logging_mixin.py:109} INFO - Running <TaskInstance: meeting_project492.merge_data 2024-03-09T02:00:00+00:00 [running]> on host 62b9685fb4d1
[2024-03-09 03:00:08,972] {taskinstance.py:1254} INFO - Exporting the following env vars:
AIRFLOW_CTX_DAG_OWNER=***
AIRFLOW_CTX_DAG_ID=meeting_project492
AIRFLOW_CTX_TASK_ID=merge_data
AIRFLOW_CTX_EXECUTION_DATE=2024-03-09T02:00:00+00:00
AIRFLOW_CTX_DAG_RUN_ID=scheduled__2024-03-09T02:00:00+00:00
[2024-03-09 03:00:09,000] {taskinstance.py:1463} ERROR - Task failed with exception
Traceback (most recent call last):
  File "/home/airflow/.local/lib/python3.6/site-packages/airflow/models/taskinstance.py", line 1165, in _run_raw_task
    self._prepare_and_execute_task_with_callbacks(context, task)
  File "/home/airflow/.local/lib/python3.6/site-packages/airflow/models/taskinstance.py", line 1283, in _prepare_and_execute_task_with_callbacks
    result = self._execute_task(context, task_copy)
  File "/home/airflow/.local/lib/python3.6/site-packages/airflow/models/taskinstance.py", line 1313, in _execute_task
    result = task_copy.execute(context=context)
  File "/home/airflow/.local/lib/python3.6/site-packages/airflow/operators/python.py", line 150, in execute
    return_value = self.execute_callable()
  File "/home/airflow/.local/lib/python3.6/site-packages/airflow/operators/python.py", line 161, in execute_callable
    return self.python_callable(*self.op_args, **self.op_kwargs)
  File "/opt/airflow/dags/first_dag.py", line 102, in merge_data
    df_meet_fol_ans_com_obj = df_meet_fol_ans_com.merge(df_obj, on = ["folderId", "meetId"], how = 'lef')
  File "/home/airflow/.local/lib/python3.6/site-packages/pandas/core/frame.py", line 7963, in merge
    validate=validate,
  File "/home/airflow/.local/lib/python3.6/site-packages/pandas/core/reshape/merge.py", line 89, in merge
    return op.get_result()
  File "/home/airflow/.local/lib/python3.6/site-packages/pandas/core/reshape/merge.py", line 668, in get_result
    join_index, left_indexer, right_indexer = self._get_join_info()
  File "/home/airflow/.local/lib/python3.6/site-packages/pandas/core/reshape/merge.py", line 884, in _get_join_info
    (left_indexer, right_indexer) = self._get_join_indexers()
  File "/home/airflow/.local/lib/python3.6/site-packages/pandas/core/reshape/merge.py", line 863, in _get_join_indexers
    self.left_join_keys, self.right_join_keys, sort=self.sort, how=self.how
  File "/home/airflow/.local/lib/python3.6/site-packages/pandas/core/reshape/merge.py", line 1353, in _get_join_indexers
    }[how]
KeyError: 'lef'
[2024-03-09 03:00:09,003] {taskinstance.py:1513} INFO - Marking task as FAILED. dag_id=meeting_project492, task_id=merge_data, execution_date=20240309T020000, start_date=20240309T030008, end_date=20240309T030009
[2024-03-09 03:00:09,056] {local_task_job.py:151} INFO - Task exited with return code 1
[2024-03-09 03:00:09,077] {local_task_job.py:261} INFO - 0 downstream tasks scheduled from follow-on schedule check
