[2024-03-11 04:40:30,890] {taskinstance.py:903} INFO - Dependencies all met for <TaskInstance: meeting_project492.merge_data 2024-03-11T04:40:26.004033+00:00 [queued]>
[2024-03-11 04:40:30,908] {taskinstance.py:903} INFO - Dependencies all met for <TaskInstance: meeting_project492.merge_data 2024-03-11T04:40:26.004033+00:00 [queued]>
[2024-03-11 04:40:30,908] {taskinstance.py:1095} INFO - 
--------------------------------------------------------------------------------
[2024-03-11 04:40:30,908] {taskinstance.py:1096} INFO - Starting attempt 1 of 1
[2024-03-11 04:40:30,908] {taskinstance.py:1097} INFO - 
--------------------------------------------------------------------------------
[2024-03-11 04:40:30,917] {taskinstance.py:1115} INFO - Executing <Task(PythonOperator): merge_data> on 2024-03-11T04:40:26.004033+00:00
[2024-03-11 04:40:30,922] {standard_task_runner.py:52} INFO - Started process 713 to run task
[2024-03-11 04:40:30,924] {standard_task_runner.py:76} INFO - Running: ['***', 'tasks', 'run', 'meeting_project492', 'merge_data', '2024-03-11T04:40:26.004033+00:00', '--job-id', '649', '--pool', 'default_pool', '--raw', '--subdir', 'DAGS_FOLDER/first_dag.py', '--cfg-path', '/tmp/tmpi2ui_43v', '--error-file', '/tmp/tmp3_qdz7_4']
[2024-03-11 04:40:30,926] {standard_task_runner.py:77} INFO - Job 649: Subtask merge_data
[2024-03-11 04:40:30,961] {logging_mixin.py:109} INFO - Running <TaskInstance: meeting_project492.merge_data 2024-03-11T04:40:26.004033+00:00 [running]> on host a354bf513529
[2024-03-11 04:40:31,008] {taskinstance.py:1254} INFO - Exporting the following env vars:
AIRFLOW_CTX_DAG_OWNER=***
AIRFLOW_CTX_DAG_ID=meeting_project492
AIRFLOW_CTX_TASK_ID=merge_data
AIRFLOW_CTX_EXECUTION_DATE=2024-03-11T04:40:26.004033+00:00
AIRFLOW_CTX_DAG_RUN_ID=manual__2024-03-11T04:40:26.004033+00:00
[2024-03-11 04:40:31,043] {taskinstance.py:1463} ERROR - Task failed with exception
Traceback (most recent call last):
  File "/home/airflow/.local/lib/python3.6/site-packages/airflow/models/taskinstance.py", line 1165, in _run_raw_task
    self._prepare_and_execute_task_with_callbacks(context, task)
  File "/home/airflow/.local/lib/python3.6/site-packages/airflow/models/taskinstance.py", line 1283, in _prepare_and_execute_task_with_callbacks
    result = self._execute_task(context, task_copy)
  File "/home/airflow/.local/lib/python3.6/site-packages/airflow/models/taskinstance.py", line 1313, in _execute_task
    result = task_copy.execute(context=context)
  File "/home/airflow/.local/lib/python3.6/site-packages/airflow/operators/python.py", line 150, in execute
    return_value = self.execute_callable()
  File "/home/airflow/.local/lib/python3.6/site-packages/airflow/operators/python.py", line 161, in execute_callable
    return self.python_callable(*self.op_args, **self.op_kwargs)
  File "/opt/airflow/dags/first_dag.py", line 110, in merge_data
    df_meet_fol_ans_com_obj.loc["no_ans"] = [np.int64(0), np.int64(1)]
  File "/home/airflow/.local/lib/python3.6/site-packages/pandas/core/indexing.py", line 670, in __setitem__
    iloc._setitem_with_indexer(indexer, value)
  File "/home/airflow/.local/lib/python3.6/site-packages/pandas/core/indexing.py", line 1626, in _setitem_with_indexer
    self._setitem_with_indexer_missing(indexer, value)
  File "/home/airflow/.local/lib/python3.6/site-packages/pandas/core/indexing.py", line 1856, in _setitem_with_indexer_missing
    raise ValueError("cannot set a row with mismatched columns")
ValueError: cannot set a row with mismatched columns
[2024-03-11 04:40:31,045] {taskinstance.py:1513} INFO - Marking task as FAILED. dag_id=meeting_project492, task_id=merge_data, execution_date=20240311T044026, start_date=20240311T044030, end_date=20240311T044031
[2024-03-11 04:40:31,096] {local_task_job.py:151} INFO - Task exited with return code 1
[2024-03-11 04:40:31,116] {local_task_job.py:261} INFO - 0 downstream tasks scheduled from follow-on schedule check
