[2023-12-02 10:47:48,091] {taskinstance.py:903} INFO - Dependencies all met for <TaskInstance: i_can_do_it_and_i_will_do.get_data 2023-12-02T10:47:46.663609+00:00 [queued]>
[2023-12-02 10:47:48,100] {taskinstance.py:903} INFO - Dependencies all met for <TaskInstance: i_can_do_it_and_i_will_do.get_data 2023-12-02T10:47:46.663609+00:00 [queued]>
[2023-12-02 10:47:48,100] {taskinstance.py:1095} INFO - 
--------------------------------------------------------------------------------
[2023-12-02 10:47:48,100] {taskinstance.py:1096} INFO - Starting attempt 1 of 1
[2023-12-02 10:47:48,100] {taskinstance.py:1097} INFO - 
--------------------------------------------------------------------------------
[2023-12-02 10:47:48,114] {taskinstance.py:1115} INFO - Executing <Task(PythonOperator): get_data> on 2023-12-02T10:47:46.663609+00:00
[2023-12-02 10:47:48,117] {standard_task_runner.py:52} INFO - Started process 2257 to run task
[2023-12-02 10:47:48,120] {standard_task_runner.py:76} INFO - Running: ['***', 'tasks', 'run', 'i_can_do_it_and_i_will_do', 'get_data', '2023-12-02T10:47:46.663609+00:00', '--job-id', '8', '--pool', 'default_pool', '--raw', '--subdir', 'DAGS_FOLDER/first_dag.py', '--cfg-path', '/tmp/tmp8rkf65fz', '--error-file', '/tmp/tmpq4sls4u0']
[2023-12-02 10:47:48,122] {standard_task_runner.py:77} INFO - Job 8: Subtask get_data
[2023-12-02 10:47:48,157] {logging_mixin.py:109} INFO - Running <TaskInstance: i_can_do_it_and_i_will_do.get_data 2023-12-02T10:47:46.663609+00:00 [running]> on host 59679203acd5
[2023-12-02 10:47:48,203] {taskinstance.py:1254} INFO - Exporting the following env vars:
AIRFLOW_CTX_DAG_OWNER=***
AIRFLOW_CTX_DAG_ID=i_can_do_it_and_i_will_do
AIRFLOW_CTX_TASK_ID=get_data
AIRFLOW_CTX_EXECUTION_DATE=2023-12-02T10:47:46.663609+00:00
AIRFLOW_CTX_DAG_RUN_ID=manual__2023-12-02T10:47:46.663609+00:00
[2023-12-02 10:47:48,212] {base.py:79} INFO - Using connection to: id: ***_db. Host: db.oymrhotncbnylwsroxra.supabase.co, Port: 5432, Schema: db_test, Login: ***, Password: ***, extra: {}
[2023-12-02 10:47:48,775] {taskinstance.py:1463} ERROR - Task failed with exception
Traceback (most recent call last):
  File "/home/airflow/.local/lib/python3.6/site-packages/airflow/models/taskinstance.py", line 1165, in _run_raw_task
    self._prepare_and_execute_task_with_callbacks(context, task)
  File "/home/airflow/.local/lib/python3.6/site-packages/airflow/models/taskinstance.py", line 1283, in _prepare_and_execute_task_with_callbacks
    result = self._execute_task(context, task_copy)
  File "/home/airflow/.local/lib/python3.6/site-packages/airflow/models/taskinstance.py", line 1313, in _execute_task
    result = task_copy.execute(context=context)
  File "/home/airflow/.local/lib/python3.6/site-packages/airflow/operators/python.py", line 150, in execute
    return_value = self.execute_callable()
  File "/home/airflow/.local/lib/python3.6/site-packages/airflow/operators/python.py", line 161, in execute_callable
    return self.python_callable(*self.op_args, **self.op_kwargs)
  File "/opt/airflow/dags/first_dag.py", line 19, in get_data
    pg_conn = pg_hook.get_conn()
  File "/home/airflow/.local/lib/python3.6/site-packages/airflow/providers/postgres/hooks/postgres.py", line 115, in get_conn
    self.conn = psycopg2.connect(**conn_args)
  File "/home/airflow/.local/lib/python3.6/site-packages/psycopg2/__init__.py", line 122, in connect
    conn = _connect(dsn, connection_factory=connection_factory, **kwasync)
psycopg2.OperationalError: FATAL:  password authentication failed for user "***"
FATAL:  password authentication failed for user "***"

[2023-12-02 10:47:48,777] {taskinstance.py:1513} INFO - Marking task as FAILED. dag_id=i_can_do_it_and_i_will_do, task_id=get_data, execution_date=20231202T104746, start_date=20231202T104748, end_date=20231202T104748
[2023-12-02 10:47:48,814] {local_task_job.py:151} INFO - Task exited with return code 1
[2023-12-02 10:47:48,835] {local_task_job.py:261} INFO - 0 downstream tasks scheduled from follow-on schedule check
