[2023-12-02 11:28:50,819] {taskinstance.py:903} INFO - Dependencies all met for <TaskInstance: i_can_do_it_and_i_will_do.get_data 2023-12-02T11:28:48.992998+00:00 [queued]>
[2023-12-02 11:28:50,833] {taskinstance.py:903} INFO - Dependencies all met for <TaskInstance: i_can_do_it_and_i_will_do.get_data 2023-12-02T11:28:48.992998+00:00 [queued]>
[2023-12-02 11:28:50,834] {taskinstance.py:1095} INFO - 
--------------------------------------------------------------------------------
[2023-12-02 11:28:50,834] {taskinstance.py:1096} INFO - Starting attempt 1 of 1
[2023-12-02 11:28:50,834] {taskinstance.py:1097} INFO - 
--------------------------------------------------------------------------------
[2023-12-02 11:28:50,842] {taskinstance.py:1115} INFO - Executing <Task(PythonOperator): get_data> on 2023-12-02T11:28:48.992998+00:00
[2023-12-02 11:28:50,847] {standard_task_runner.py:52} INFO - Started process 3480 to run task
[2023-12-02 11:28:50,849] {standard_task_runner.py:76} INFO - Running: ['***', 'tasks', 'run', 'i_can_do_it_and_i_will_do', 'get_data', '2023-12-02T11:28:48.992998+00:00', '--job-id', '18', '--pool', 'default_pool', '--raw', '--subdir', 'DAGS_FOLDER/first_dag.py', '--cfg-path', '/tmp/tmpcy6pg41g', '--error-file', '/tmp/tmp2b463win']
[2023-12-02 11:28:50,851] {standard_task_runner.py:77} INFO - Job 18: Subtask get_data
[2023-12-02 11:28:50,889] {logging_mixin.py:109} INFO - Running <TaskInstance: i_can_do_it_and_i_will_do.get_data 2023-12-02T11:28:48.992998+00:00 [running]> on host d8ab40647e8d
[2023-12-02 11:28:50,933] {taskinstance.py:1254} INFO - Exporting the following env vars:
AIRFLOW_CTX_DAG_OWNER=***
AIRFLOW_CTX_DAG_ID=i_can_do_it_and_i_will_do
AIRFLOW_CTX_TASK_ID=get_data
AIRFLOW_CTX_EXECUTION_DATE=2023-12-02T11:28:48.992998+00:00
AIRFLOW_CTX_DAG_RUN_ID=manual__2023-12-02T11:28:48.992998+00:00
[2023-12-02 11:28:52,100] {taskinstance.py:1463} ERROR - Task failed with exception
Traceback (most recent call last):
  File "/home/airflow/.local/lib/python3.6/site-packages/airflow/models/taskinstance.py", line 1165, in _run_raw_task
    self._prepare_and_execute_task_with_callbacks(context, task)
  File "/home/airflow/.local/lib/python3.6/site-packages/airflow/models/taskinstance.py", line 1283, in _prepare_and_execute_task_with_callbacks
    result = self._execute_task(context, task_copy)
  File "/home/airflow/.local/lib/python3.6/site-packages/airflow/models/taskinstance.py", line 1313, in _execute_task
    result = task_copy.execute(context=context)
  File "/home/airflow/.local/lib/python3.6/site-packages/airflow/operators/python.py", line 150, in execute
    return_value = self.execute_callable()
  File "/home/airflow/.local/lib/python3.6/site-packages/airflow/operators/python.py", line 161, in execute_callable
    return self.python_callable(*self.op_args, **self.op_kwargs)
  File "/opt/airflow/dags/first_dag.py", line 16, in get_data
    df.to_csv(Variable.get('data_local'), index = False)
NameError: name 'Variable' is not defined
[2023-12-02 11:28:52,101] {taskinstance.py:1513} INFO - Marking task as FAILED. dag_id=i_can_do_it_and_i_will_do, task_id=get_data, execution_date=20231202T112848, start_date=20231202T112850, end_date=20231202T112852
[2023-12-02 11:28:52,146] {local_task_job.py:151} INFO - Task exited with return code 1
[2023-12-02 11:28:52,168] {local_task_job.py:261} INFO - 0 downstream tasks scheduled from follow-on schedule check
